ERROR|2024-06-28 10:36:49,615|views:26|posts.views>> User has no profile.
Traceback (most recent call last):
  File "/service/core/views.py", line 23, in dispatch
    return super().dispatch(request, *args, **kwargs)
           ^^^^^^^^^^^^^^^^^^^^^^^^^^^^^^^^^^^^^^^^^^
  File "/usr/local/lib/python3.12/site-packages/django/views/generic/base.py", line 143, in dispatch
    return handler(request, *args, **kwargs)
           ^^^^^^^^^^^^^^^^^^^^^^^^^^^^^^^^^
  File "/usr/local/lib/python3.12/site-packages/django/views/generic/list.py", line 154, in get
    self.object_list = self.get_queryset()
                       ^^^^^^^^^^^^^^^^^^^
  File "/service/posts/mixins.py", line 28, in get_queryset
    author.id for author in UsersService.get_suggested_users_per_user(user)
                            ^^^^^^^^^^^^^^^^^^^^^^^^^^^^^^^^^^^^^^^^^^^^^^^
  File "/service/users/services/users_service.py", line 36, in get_suggested_users_per_user
    profile = user.profile
              ^^^^^^^^^^^^
  File "/usr/local/lib/python3.12/site-packages/django/utils/functional.py", line 253, in inner
    return func(_wrapped, *args)
           ^^^^^^^^^^^^^^^^^^^^^
  File "/usr/local/lib/python3.12/site-packages/django/db/models/fields/related_descriptors.py", line 525, in __get__
    raise self.RelatedObjectDoesNotExist(
django.contrib.auth.models.User.profile.RelatedObjectDoesNotExist: User has no profile.
ERROR|2024-06-28 10:36:51,152|views:26|posts.views>> User has no profile.
Traceback (most recent call last):
  File "/service/core/views.py", line 23, in dispatch
    return super().dispatch(request, *args, **kwargs)
           ^^^^^^^^^^^^^^^^^^^^^^^^^^^^^^^^^^^^^^^^^^
  File "/usr/local/lib/python3.12/site-packages/django/views/generic/base.py", line 143, in dispatch
    return handler(request, *args, **kwargs)
           ^^^^^^^^^^^^^^^^^^^^^^^^^^^^^^^^^
  File "/usr/local/lib/python3.12/site-packages/django/views/generic/list.py", line 154, in get
    self.object_list = self.get_queryset()
                       ^^^^^^^^^^^^^^^^^^^
  File "/service/posts/mixins.py", line 28, in get_queryset
    author.id for author in UsersService.get_suggested_users_per_user(user)
                            ^^^^^^^^^^^^^^^^^^^^^^^^^^^^^^^^^^^^^^^^^^^^^^^
  File "/service/users/services/users_service.py", line 36, in get_suggested_users_per_user
    profile = user.profile
              ^^^^^^^^^^^^
  File "/usr/local/lib/python3.12/site-packages/django/utils/functional.py", line 253, in inner
    return func(_wrapped, *args)
           ^^^^^^^^^^^^^^^^^^^^^
  File "/usr/local/lib/python3.12/site-packages/django/db/models/fields/related_descriptors.py", line 525, in __get__
    raise self.RelatedObjectDoesNotExist(
django.contrib.auth.models.User.profile.RelatedObjectDoesNotExist: User has no profile.
ERROR|2024-06-28 10:36:51,458|views:26|posts.views>> User has no profile.
Traceback (most recent call last):
  File "/service/core/views.py", line 23, in dispatch
    return super().dispatch(request, *args, **kwargs)
           ^^^^^^^^^^^^^^^^^^^^^^^^^^^^^^^^^^^^^^^^^^
  File "/usr/local/lib/python3.12/site-packages/django/views/generic/base.py", line 143, in dispatch
    return handler(request, *args, **kwargs)
           ^^^^^^^^^^^^^^^^^^^^^^^^^^^^^^^^^
  File "/usr/local/lib/python3.12/site-packages/django/views/generic/list.py", line 154, in get
    self.object_list = self.get_queryset()
                       ^^^^^^^^^^^^^^^^^^^
  File "/service/posts/mixins.py", line 28, in get_queryset
    author.id for author in UsersService.get_suggested_users_per_user(user)
                            ^^^^^^^^^^^^^^^^^^^^^^^^^^^^^^^^^^^^^^^^^^^^^^^
  File "/service/users/services/users_service.py", line 36, in get_suggested_users_per_user
    profile = user.profile
              ^^^^^^^^^^^^
  File "/usr/local/lib/python3.12/site-packages/django/utils/functional.py", line 253, in inner
    return func(_wrapped, *args)
           ^^^^^^^^^^^^^^^^^^^^^
  File "/usr/local/lib/python3.12/site-packages/django/db/models/fields/related_descriptors.py", line 525, in __get__
    raise self.RelatedObjectDoesNotExist(
django.contrib.auth.models.User.profile.RelatedObjectDoesNotExist: User has no profile.
ERROR|2024-06-28 10:36:51,951|views:26|posts.views>> User has no profile.
Traceback (most recent call last):
  File "/service/core/views.py", line 23, in dispatch
    return super().dispatch(request, *args, **kwargs)
           ^^^^^^^^^^^^^^^^^^^^^^^^^^^^^^^^^^^^^^^^^^
  File "/usr/local/lib/python3.12/site-packages/django/views/generic/base.py", line 143, in dispatch
    return handler(request, *args, **kwargs)
           ^^^^^^^^^^^^^^^^^^^^^^^^^^^^^^^^^
  File "/usr/local/lib/python3.12/site-packages/django/views/generic/list.py", line 154, in get
    self.object_list = self.get_queryset()
                       ^^^^^^^^^^^^^^^^^^^
  File "/service/posts/mixins.py", line 28, in get_queryset
    author.id for author in UsersService.get_suggested_users_per_user(user)
                            ^^^^^^^^^^^^^^^^^^^^^^^^^^^^^^^^^^^^^^^^^^^^^^^
  File "/service/users/services/users_service.py", line 36, in get_suggested_users_per_user
    profile = user.profile
              ^^^^^^^^^^^^
  File "/usr/local/lib/python3.12/site-packages/django/utils/functional.py", line 253, in inner
    return func(_wrapped, *args)
           ^^^^^^^^^^^^^^^^^^^^^
  File "/usr/local/lib/python3.12/site-packages/django/db/models/fields/related_descriptors.py", line 525, in __get__
    raise self.RelatedObjectDoesNotExist(
django.contrib.auth.models.User.profile.RelatedObjectDoesNotExist: User has no profile.
ERROR|2024-06-28 10:36:53,496|views:26|posts.views>> User has no profile.
Traceback (most recent call last):
  File "/service/core/views.py", line 23, in dispatch
    return super().dispatch(request, *args, **kwargs)
           ^^^^^^^^^^^^^^^^^^^^^^^^^^^^^^^^^^^^^^^^^^
  File "/usr/local/lib/python3.12/site-packages/django/views/generic/base.py", line 143, in dispatch
    return handler(request, *args, **kwargs)
           ^^^^^^^^^^^^^^^^^^^^^^^^^^^^^^^^^
  File "/usr/local/lib/python3.12/site-packages/django/views/generic/list.py", line 154, in get
    self.object_list = self.get_queryset()
                       ^^^^^^^^^^^^^^^^^^^
  File "/service/posts/mixins.py", line 28, in get_queryset
    author.id for author in UsersService.get_suggested_users_per_user(user)
                            ^^^^^^^^^^^^^^^^^^^^^^^^^^^^^^^^^^^^^^^^^^^^^^^
  File "/service/users/services/users_service.py", line 36, in get_suggested_users_per_user
    profile = user.profile
              ^^^^^^^^^^^^
  File "/usr/local/lib/python3.12/site-packages/django/utils/functional.py", line 253, in inner
    return func(_wrapped, *args)
           ^^^^^^^^^^^^^^^^^^^^^
  File "/usr/local/lib/python3.12/site-packages/django/db/models/fields/related_descriptors.py", line 525, in __get__
    raise self.RelatedObjectDoesNotExist(
django.contrib.auth.models.User.profile.RelatedObjectDoesNotExist: User has no profile.
ERROR|2024-06-28 10:36:54,024|views:26|posts.views>> User has no profile.
Traceback (most recent call last):
  File "/service/core/views.py", line 23, in dispatch
    return super().dispatch(request, *args, **kwargs)
           ^^^^^^^^^^^^^^^^^^^^^^^^^^^^^^^^^^^^^^^^^^
  File "/usr/local/lib/python3.12/site-packages/django/views/generic/base.py", line 143, in dispatch
    return handler(request, *args, **kwargs)
           ^^^^^^^^^^^^^^^^^^^^^^^^^^^^^^^^^
  File "/usr/local/lib/python3.12/site-packages/django/views/generic/list.py", line 154, in get
    self.object_list = self.get_queryset()
                       ^^^^^^^^^^^^^^^^^^^
  File "/service/posts/mixins.py", line 28, in get_queryset
    author.id for author in UsersService.get_suggested_users_per_user(user)
                            ^^^^^^^^^^^^^^^^^^^^^^^^^^^^^^^^^^^^^^^^^^^^^^^
  File "/service/users/services/users_service.py", line 36, in get_suggested_users_per_user
    profile = user.profile
              ^^^^^^^^^^^^
  File "/usr/local/lib/python3.12/site-packages/django/utils/functional.py", line 253, in inner
    return func(_wrapped, *args)
           ^^^^^^^^^^^^^^^^^^^^^
  File "/usr/local/lib/python3.12/site-packages/django/db/models/fields/related_descriptors.py", line 525, in __get__
    raise self.RelatedObjectDoesNotExist(
django.contrib.auth.models.User.profile.RelatedObjectDoesNotExist: User has no profile.
ERROR|2024-06-28 10:36:54,551|views:26|posts.views>> User has no profile.
Traceback (most recent call last):
  File "/service/core/views.py", line 23, in dispatch
    return super().dispatch(request, *args, **kwargs)
           ^^^^^^^^^^^^^^^^^^^^^^^^^^^^^^^^^^^^^^^^^^
  File "/usr/local/lib/python3.12/site-packages/django/views/generic/base.py", line 143, in dispatch
    return handler(request, *args, **kwargs)
           ^^^^^^^^^^^^^^^^^^^^^^^^^^^^^^^^^
  File "/usr/local/lib/python3.12/site-packages/django/views/generic/list.py", line 154, in get
    self.object_list = self.get_queryset()
                       ^^^^^^^^^^^^^^^^^^^
  File "/service/posts/mixins.py", line 28, in get_queryset
    author.id for author in UsersService.get_suggested_users_per_user(user)
                            ^^^^^^^^^^^^^^^^^^^^^^^^^^^^^^^^^^^^^^^^^^^^^^^
  File "/service/users/services/users_service.py", line 36, in get_suggested_users_per_user
    profile = user.profile
              ^^^^^^^^^^^^
  File "/usr/local/lib/python3.12/site-packages/django/utils/functional.py", line 253, in inner
    return func(_wrapped, *args)
           ^^^^^^^^^^^^^^^^^^^^^
  File "/usr/local/lib/python3.12/site-packages/django/db/models/fields/related_descriptors.py", line 525, in __get__
    raise self.RelatedObjectDoesNotExist(
django.contrib.auth.models.User.profile.RelatedObjectDoesNotExist: User has no profile.
ERROR|2024-06-28 10:36:55,263|views:26|posts.views>> User has no profile.
Traceback (most recent call last):
  File "/service/core/views.py", line 23, in dispatch
    return super().dispatch(request, *args, **kwargs)
           ^^^^^^^^^^^^^^^^^^^^^^^^^^^^^^^^^^^^^^^^^^
  File "/usr/local/lib/python3.12/site-packages/django/views/generic/base.py", line 143, in dispatch
    return handler(request, *args, **kwargs)
           ^^^^^^^^^^^^^^^^^^^^^^^^^^^^^^^^^
  File "/usr/local/lib/python3.12/site-packages/django/views/generic/list.py", line 154, in get
    self.object_list = self.get_queryset()
                       ^^^^^^^^^^^^^^^^^^^
  File "/service/posts/mixins.py", line 28, in get_queryset
    author.id for author in UsersService.get_suggested_users_per_user(user)
                            ^^^^^^^^^^^^^^^^^^^^^^^^^^^^^^^^^^^^^^^^^^^^^^^
  File "/service/users/services/users_service.py", line 36, in get_suggested_users_per_user
    profile = user.profile
              ^^^^^^^^^^^^
  File "/usr/local/lib/python3.12/site-packages/django/utils/functional.py", line 253, in inner
    return func(_wrapped, *args)
           ^^^^^^^^^^^^^^^^^^^^^
  File "/usr/local/lib/python3.12/site-packages/django/db/models/fields/related_descriptors.py", line 525, in __get__
    raise self.RelatedObjectDoesNotExist(
django.contrib.auth.models.User.profile.RelatedObjectDoesNotExist: User has no profile.
ERROR|2024-06-28 10:39:18,901|views:20|posts.views>> User has no profile.
Traceback (most recent call last):
  File "/service/core/views.py", line 31, in dispatch
    return super().dispatch(request, *args, **kwargs)
           ^^^^^^^^^^^^^^^^^^^^^^^^^^^^^^^^^^^^^^^^^^
  File "/usr/local/lib/python3.12/site-packages/django/views/generic/base.py", line 143, in dispatch
    return handler(request, *args, **kwargs)
           ^^^^^^^^^^^^^^^^^^^^^^^^^^^^^^^^^
  File "/usr/local/lib/python3.12/site-packages/django/views/generic/list.py", line 154, in get
    self.object_list = self.get_queryset()
                       ^^^^^^^^^^^^^^^^^^^
  File "/service/posts/mixins.py", line 28, in get_queryset
    author.id for author in UsersService.get_suggested_users_per_user(user)
                            ^^^^^^^^^^^^^^^^^^^^^^^^^^^^^^^^^^^^^^^^^^^^^^^
  File "/service/users/services/users_service.py", line 36, in get_suggested_users_per_user
    profile = user.profile
              ^^^^^^^^^^^^
  File "/usr/local/lib/python3.12/site-packages/django/utils/functional.py", line 253, in inner
    return func(_wrapped, *args)
           ^^^^^^^^^^^^^^^^^^^^^
  File "/usr/local/lib/python3.12/site-packages/django/db/models/fields/related_descriptors.py", line 525, in __get__
    raise self.RelatedObjectDoesNotExist(
django.contrib.auth.models.User.profile.RelatedObjectDoesNotExist: User has no profile.
ERROR|2024-06-28 10:41:45,262|views:20|posts.views>> User has no profile.
Traceback (most recent call last):
  File "/service/core/views.py", line 31, in dispatch
    return super().dispatch(request, *args, **kwargs)
           ^^^^^^^^^^^^^^^^^^^^^^^^^^^^^^^^^^^^^^^^^^
  File "/usr/local/lib/python3.12/site-packages/django/views/generic/base.py", line 143, in dispatch
    return handler(request, *args, **kwargs)
           ^^^^^^^^^^^^^^^^^^^^^^^^^^^^^^^^^
  File "/usr/local/lib/python3.12/site-packages/django/views/generic/list.py", line 154, in get
    self.object_list = self.get_queryset()
                       ^^^^^^^^^^^^^^^^^^^
  File "/service/posts/mixins.py", line 26, in get_queryset
    ]
      
  File "/service/users/services/users_service.py", line 37, in get_suggested_users_per_user
    profile = user.profile
              ^^^^^^^^^^^^
  File "/usr/local/lib/python3.12/site-packages/django/utils/functional.py", line 253, in inner
    return func(_wrapped, *args)
           ^^^^^^^^^^^^^^^^^^^^^
  File "/usr/local/lib/python3.12/site-packages/django/db/models/fields/related_descriptors.py", line 525, in __get__
    raise self.RelatedObjectDoesNotExist(
django.contrib.auth.models.User.profile.RelatedObjectDoesNotExist: User has no profile.
ERROR|2024-06-28 12:06:34,461|views:20|posts.views>> 'POSTS_FEED'
Traceback (most recent call last):
  File "/service/core/views.py", line 31, in dispatch
    return super().dispatch(request, *args, **kwargs)
           ^^^^^^^^^^^^^^^^^^^^^^^^^^^^^^^^^^^^^^^^^^
  File "/usr/local/lib/python3.12/site-packages/django/views/generic/base.py", line 143, in dispatch
    return handler(request, *args, **kwargs)
           ^^^^^^^^^^^^^^^^^^^^^^^^^^^^^^^^^
  File "/usr/local/lib/python3.12/site-packages/django/views/generic/list.py", line 154, in get
    self.object_list = self.get_queryset()
                       ^^^^^^^^^^^^^^^^^^^
  File "/service/posts/mixins.py", line 18, in get_queryset
    cache_key = CACHE_KEYS["POSTS_FEED"].format(
                ~~~~~~~~~~^^^^^^^^^^^^^^
KeyError: 'POSTS_FEED'
ERROR|2024-06-28 12:06:52,158|views:20|posts.views>> 'POSTS_FEED_VERSION'
Traceback (most recent call last):
  File "/service/core/views.py", line 31, in dispatch
    return super().dispatch(request, *args, **kwargs)
           ^^^^^^^^^^^^^^^^^^^^^^^^^^^^^^^^^^^^^^^^^^
  File "/usr/local/lib/python3.12/site-packages/django/views/generic/base.py", line 143, in dispatch
    return handler(request, *args, **kwargs)
           ^^^^^^^^^^^^^^^^^^^^^^^^^^^^^^^^^
  File "/usr/local/lib/python3.12/site-packages/django/views/generic/list.py", line 154, in get
    self.object_list = self.get_queryset()
                       ^^^^^^^^^^^^^^^^^^^
  File "/service/posts/mixins.py", line 20, in get_queryset
    version=cache.get(CACHE_KEYS["POSTS_FEED_VERSION"], 0)
                      ~~~~~~~~~~^^^^^^^^^^^^^^^^^^^^^^
KeyError: 'POSTS_FEED_VERSION'
ERROR|2024-06-28 12:06:52,897|views:20|posts.views>> 'POSTS_FEED_VERSION'
Traceback (most recent call last):
  File "/service/core/views.py", line 31, in dispatch
    return super().dispatch(request, *args, **kwargs)
           ^^^^^^^^^^^^^^^^^^^^^^^^^^^^^^^^^^^^^^^^^^
  File "/usr/local/lib/python3.12/site-packages/django/views/generic/base.py", line 143, in dispatch
    return handler(request, *args, **kwargs)
           ^^^^^^^^^^^^^^^^^^^^^^^^^^^^^^^^^
  File "/usr/local/lib/python3.12/site-packages/django/views/generic/list.py", line 154, in get
    self.object_list = self.get_queryset()
                       ^^^^^^^^^^^^^^^^^^^
  File "/service/posts/mixins.py", line 20, in get_queryset
    version=cache.get(CACHE_KEYS["POSTS_FEED_VERSION"], 0)
                      ~~~~~~~~~~^^^^^^^^^^^^^^^^^^^^^^
KeyError: 'POSTS_FEED_VERSION'
ERROR|2024-06-28 12:06:53,511|views:20|posts.views>> 'POSTS_FEED_VERSION'
Traceback (most recent call last):
  File "/service/core/views.py", line 31, in dispatch
    return super().dispatch(request, *args, **kwargs)
           ^^^^^^^^^^^^^^^^^^^^^^^^^^^^^^^^^^^^^^^^^^
  File "/usr/local/lib/python3.12/site-packages/django/views/generic/base.py", line 143, in dispatch
    return handler(request, *args, **kwargs)
           ^^^^^^^^^^^^^^^^^^^^^^^^^^^^^^^^^
  File "/usr/local/lib/python3.12/site-packages/django/views/generic/list.py", line 154, in get
    self.object_list = self.get_queryset()
                       ^^^^^^^^^^^^^^^^^^^
  File "/service/posts/mixins.py", line 20, in get_queryset
    version=cache.get(CACHE_KEYS["POSTS_FEED_VERSION"], 0)
                      ~~~~~~~~~~^^^^^^^^^^^^^^^^^^^^^^
KeyError: 'POSTS_FEED_VERSION'
ERROR|2024-06-28 12:07:03,115|views:20|posts.views>> 'user_id'
Traceback (most recent call last):
  File "/service/core/views.py", line 31, in dispatch
    return super().dispatch(request, *args, **kwargs)
           ^^^^^^^^^^^^^^^^^^^^^^^^^^^^^^^^^^^^^^^^^^
  File "/usr/local/lib/python3.12/site-packages/django/views/generic/base.py", line 143, in dispatch
    return handler(request, *args, **kwargs)
           ^^^^^^^^^^^^^^^^^^^^^^^^^^^^^^^^^
  File "/usr/local/lib/python3.12/site-packages/django/views/generic/list.py", line 154, in get
    self.object_list = self.get_queryset()
                       ^^^^^^^^^^^^^^^^^^^
  File "/service/posts/mixins.py", line 18, in get_queryset
    cache_key = CACHE_KEYS["POSTS_LIST"].format(
                ^^^^^^^^^^^^^^^^^^^^^^^^^^^^^^^^
KeyError: 'user_id'
